[2024-07-12T00:19:11.439+0000] {taskinstance.py:1979} INFO - Dependencies all met for dep_context=non-requeueable deps ti=<TaskInstance: data_ingestion.ingest_task manual__2024-07-12T00:17:04.240558+00:00 [queued]>
[2024-07-12T00:19:11.443+0000] {taskinstance.py:1979} INFO - Dependencies all met for dep_context=requeueable deps ti=<TaskInstance: data_ingestion.ingest_task manual__2024-07-12T00:17:04.240558+00:00 [queued]>
[2024-07-12T00:19:11.443+0000] {taskinstance.py:2193} INFO - Starting attempt 3 of 4
[2024-07-12T00:19:11.449+0000] {taskinstance.py:2217} INFO - Executing <Task(PythonVirtualenvOperator): ingest_task> on 2024-07-12 00:17:04.240558+00:00
[2024-07-12T00:19:11.452+0000] {standard_task_runner.py:60} INFO - Started process 711 to run task
[2024-07-12T00:19:11.457+0000] {standard_task_runner.py:87} INFO - Running: ['***', 'tasks', 'run', 'data_ingestion', 'ingest_task', 'manual__2024-07-12T00:17:04.240558+00:00', '--job-id', '10', '--raw', '--subdir', 'DAGS_FOLDER/data_ingestion.py', '--cfg-path', '/tmp/tmpv86scyhj']
[2024-07-12T00:19:11.468+0000] {standard_task_runner.py:88} INFO - Job 10: Subtask ingest_task
[2024-07-12T00:19:11.488+0000] {logging_mixin.py:188} WARNING - /home/***/.local/lib/python3.8/site-packages/***/settings.py:194 DeprecationWarning: The sql_alchemy_conn option in [core] has been moved to the sql_alchemy_conn option in [database] - the old setting has been used, but please update your config.
[2024-07-12T00:19:11.510+0000] {task_command.py:423} INFO - Running <TaskInstance: data_ingestion.ingest_task manual__2024-07-12T00:17:04.240558+00:00 [running]> on host ***-scheduler
[2024-07-12T00:19:11.555+0000] {taskinstance.py:2513} INFO - Exporting env vars: AIRFLOW_CTX_DAG_OWNER='***' AIRFLOW_CTX_DAG_ID='data_ingestion' AIRFLOW_CTX_TASK_ID='ingest_task' AIRFLOW_CTX_EXECUTION_DATE='2024-07-12T00:17:04.240558+00:00' AIRFLOW_CTX_TRY_NUMBER='3' AIRFLOW_CTX_DAG_RUN_ID='manual__2024-07-12T00:17:04.240558+00:00'
[2024-07-12T00:19:12.028+0000] {process_utils.py:182} INFO - Executing cmd: /usr/local/bin/python -m virtualenv /tmp/venvdg8awc2a --python=python
[2024-07-12T00:19:12.036+0000] {process_utils.py:186} INFO - Output:
[2024-07-12T00:19:12.441+0000] {process_utils.py:190} INFO - created virtual environment CPython3.8.19.final.0-64 in 138ms
[2024-07-12T00:19:12.443+0000] {process_utils.py:190} INFO -   creator CPython3Posix(dest=/tmp/venvdg8awc2a, clear=False, no_vcs_ignore=False, global=False)
[2024-07-12T00:19:12.444+0000] {process_utils.py:190} INFO -   seeder FromAppData(download=False, pip=bundle, setuptools=bundle, wheel=bundle, via=copy, app_data_dir=/home/***/.local/share/virtualenv)
[2024-07-12T00:19:12.444+0000] {process_utils.py:190} INFO -     added seed packages: pip==24.0, setuptools==69.1.0, wheel==0.42.0
[2024-07-12T00:19:12.444+0000] {process_utils.py:190} INFO -   activators BashActivator,CShellActivator,FishActivator,NushellActivator,PowerShellActivator,PythonActivator
[2024-07-12T00:19:12.458+0000] {process_utils.py:182} INFO - Executing cmd: /tmp/venvdg8awc2a/bin/pip install -r /tmp/venvdg8awc2a/requirements.txt
[2024-07-12T00:19:12.462+0000] {process_utils.py:186} INFO - Output:
[2024-07-12T00:19:12.901+0000] {process_utils.py:190} INFO - ERROR: Can not perform a '--user' install. User site-packages are not visible in this virtualenv.
[2024-07-12T00:19:13.003+0000] {process_utils.py:190} INFO - 
[2024-07-12T00:19:13.003+0000] {process_utils.py:190} INFO - [notice] A new release of pip is available: 24.0 -> 24.1.2
[2024-07-12T00:19:13.004+0000] {process_utils.py:190} INFO - [notice] To update, run: python -m pip install --upgrade pip
[2024-07-12T00:19:15.073+0000] {taskinstance.py:2731} ERROR - Task failed with exception
Traceback (most recent call last):
  File "/home/airflow/.local/lib/python3.8/site-packages/airflow/models/taskinstance.py", line 444, in _execute_task
    result = _execute_callable(context=context, **execute_callable_kwargs)
  File "/home/airflow/.local/lib/python3.8/site-packages/airflow/models/taskinstance.py", line 414, in _execute_callable
    return execute_callable(context=context, **execute_callable_kwargs)
  File "/home/airflow/.local/lib/python3.8/site-packages/airflow/operators/python.py", line 401, in execute
    return super().execute(context=serializable_context)
  File "/home/airflow/.local/lib/python3.8/site-packages/airflow/operators/python.py", line 200, in execute
    return_value = self.execute_callable()
  File "/home/airflow/.local/lib/python3.8/site-packages/airflow/operators/python.py", line 721, in execute_callable
    self._prepare_venv(tmp_path)
  File "/home/airflow/.local/lib/python3.8/site-packages/airflow/operators/python.py", line 633, in _prepare_venv
    prepare_virtualenv(
  File "/home/airflow/.local/lib/python3.8/site-packages/airflow/utils/python_virtualenv.py", line 118, in prepare_virtualenv
    execute_in_subprocess(pip_cmd)
  File "/home/airflow/.local/lib/python3.8/site-packages/airflow/utils/process_utils.py", line 171, in execute_in_subprocess
    execute_in_subprocess_with_kwargs(cmd, cwd=cwd)
  File "/home/airflow/.local/lib/python3.8/site-packages/airflow/utils/process_utils.py", line 194, in execute_in_subprocess_with_kwargs
    raise subprocess.CalledProcessError(exit_code, cmd)
subprocess.CalledProcessError: Command '['/tmp/venvdg8awc2a/bin/pip', 'install', '-r', '/tmp/venvdg8awc2a/requirements.txt']' returned non-zero exit status 1.
[2024-07-12T00:19:15.080+0000] {taskinstance.py:1149} INFO - Marking task as UP_FOR_RETRY. dag_id=data_ingestion, task_id=ingest_task, execution_date=20240712T001704, start_date=20240712T001911, end_date=20240712T001915
[2024-07-12T00:19:15.086+0000] {standard_task_runner.py:107} ERROR - Failed to execute job 10 for task ingest_task (Command '['/tmp/venvdg8awc2a/bin/pip', 'install', '-r', '/tmp/venvdg8awc2a/requirements.txt']' returned non-zero exit status 1.; 711)
[2024-07-12T00:19:15.124+0000] {local_task_job_runner.py:234} INFO - Task exited with return code 1
[2024-07-12T00:19:15.141+0000] {taskinstance.py:3312} INFO - 0 downstream tasks scheduled from follow-on schedule check
