[2024-07-02T02:16:57.174+0000] {local_task_job_runner.py:120} INFO - ::group::Pre task execution logs
[2024-07-02T02:16:57.183+0000] {taskinstance.py:2076} INFO - Dependencies all met for dep_context=non-requeueable deps ti=<TaskInstance: data-ingestion.ingest_from_mysql scheduled__2024-06-30T15:05:00+00:00 [queued]>
[2024-07-02T02:16:57.189+0000] {taskinstance.py:2076} INFO - Dependencies all met for dep_context=requeueable deps ti=<TaskInstance: data-ingestion.ingest_from_mysql scheduled__2024-06-30T15:05:00+00:00 [queued]>
[2024-07-02T02:16:57.189+0000] {taskinstance.py:2306} INFO - Starting attempt 1 of 1
[2024-07-02T02:16:57.199+0000] {taskinstance.py:2330} INFO - Executing <Task(_PythonDecoratedOperator): ingest_from_mysql> on 2024-06-30 15:05:00+00:00
[2024-07-02T02:16:57.212+0000] {logging_mixin.py:188} WARNING - /home/***/.local/lib/python3.12/site-packages/***/task/task_runner/standard_task_runner.py:61 DeprecationWarning: This process (pid=283) is multi-threaded, use of fork() may lead to deadlocks in the child.
[2024-07-02T02:16:57.214+0000] {standard_task_runner.py:63} INFO - Started process 284 to run task
[2024-07-02T02:16:57.212+0000] {standard_task_runner.py:90} INFO - Running: ['***', 'tasks', 'run', 'data-ingestion', 'ingest_from_mysql', 'scheduled__2024-06-30T15:05:00+00:00', '--job-id', '5', '--raw', '--subdir', 'DAGS_FOLDER/data-ingestion.py', '--cfg-path', '/tmp/tmph2s9cah3']
[2024-07-02T02:16:57.215+0000] {standard_task_runner.py:91} INFO - Job 5: Subtask ingest_from_mysql
[2024-07-02T02:16:57.224+0000] {logging_mixin.py:188} WARNING - /home/***/.local/lib/python3.12/site-packages/***/settings.py:195 DeprecationWarning: The sql_alchemy_conn option in [core] has been moved to the sql_alchemy_conn option in [database] - the old setting has been used, but please update your config.
[2024-07-02T02:16:57.245+0000] {task_command.py:426} INFO - Running <TaskInstance: data-ingestion.ingest_from_mysql scheduled__2024-06-30T15:05:00+00:00 [running]> on host ***-scheduler
[2024-07-02T02:16:57.275+0000] {taskinstance.py:2648} INFO - Exporting env vars: AIRFLOW_CTX_DAG_OWNER='***' AIRFLOW_CTX_DAG_ID='data-ingestion' AIRFLOW_CTX_TASK_ID='ingest_from_mysql' AIRFLOW_CTX_EXECUTION_DATE='2024-06-30T15:05:00+00:00' AIRFLOW_CTX_TRY_NUMBER='1' AIRFLOW_CTX_DAG_RUN_ID='scheduled__2024-06-30T15:05:00+00:00'
[2024-07-02T02:16:57.509+0000] {taskinstance.py:430} INFO - ::endgroup::
[2024-07-02T02:16:57.805+0000] {pipeline.py:257} INFO - Sink configured successfully. DataHubRestEmitter: configured to talk to http://datahub-gms:8080
[2024-07-02T02:16:57.981+0000] {taskinstance.py:441} INFO - ::group::Post task execution logs
[2024-07-02T02:16:58.334+0000] {taskinstance.py:2905} ERROR - Task failed with exception
Traceback (most recent call last):
  File "/home/airflow/.local/lib/python3.12/site-packages/datahub/ingestion/api/registry.py", line 126, in _ensure_not_lazy
    plugin_class = import_path(path)
                   ^^^^^^^^^^^^^^^^^
  File "/home/airflow/.local/lib/python3.12/site-packages/datahub/ingestion/api/registry.py", line 56, in import_path
    item = importlib.import_module(module_name)
           ^^^^^^^^^^^^^^^^^^^^^^^^^^^^^^^^^^^^
  File "/usr/local/lib/python3.12/importlib/__init__.py", line 90, in import_module
    return _bootstrap._gcd_import(name[level:], package, level)
           ^^^^^^^^^^^^^^^^^^^^^^^^^^^^^^^^^^^^^^^^^^^^^^^^^^^^
  File "<frozen importlib._bootstrap>", line 1387, in _gcd_import
  File "<frozen importlib._bootstrap>", line 1360, in _find_and_load
  File "<frozen importlib._bootstrap>", line 1331, in _find_and_load_unlocked
  File "<frozen importlib._bootstrap>", line 935, in _load_unlocked
  File "<frozen importlib._bootstrap_external>", line 995, in exec_module
  File "<frozen importlib._bootstrap>", line 488, in _call_with_frames_removed
  File "/home/airflow/.local/lib/python3.12/site-packages/datahub/ingestion/source/sql/mariadb.py", line 9, in <module>
    from datahub.ingestion.source.sql.mysql import MySQLConfig, MySQLSource
  File "/home/airflow/.local/lib/python3.12/site-packages/datahub/ingestion/source/sql/mysql.py", line 18, in <module>
    from datahub.ingestion.source.sql.sql_common import (
  File "/home/airflow/.local/lib/python3.12/site-packages/datahub/ingestion/source/sql/sql_common.py", line 50, in <module>
    from datahub.ingestion.glossary.classification_mixin import (
  File "/home/airflow/.local/lib/python3.12/site-packages/datahub/ingestion/glossary/classification_mixin.py", line 8, in <module>
    from datahub_classify.helper_classes import ColumnInfo, Metadata
ModuleNotFoundError: No module named 'datahub_classify'

The above exception was the direct cause of the following exception:

Traceback (most recent call last):
  File "/home/airflow/.local/lib/python3.12/site-packages/datahub/ingestion/run/pipeline.py", line 124, in _add_init_error_context
    yield
  File "/home/airflow/.local/lib/python3.12/site-packages/datahub/ingestion/run/pipeline.py", line 272, in __init__
    source_class = source_registry.get(self.source_type)
                   ^^^^^^^^^^^^^^^^^^^^^^^^^^^^^^^^^^^^^
  File "/home/airflow/.local/lib/python3.12/site-packages/datahub/ingestion/api/registry.py", line 176, in get
    raise ConfigurationError(
datahub.configuration.common.ConfigurationError: mariadb is disabled; try running: pip install 'acryl-datahub[mariadb]'

The above exception was the direct cause of the following exception:

Traceback (most recent call last):
  File "/home/airflow/.local/lib/python3.12/site-packages/airflow/models/taskinstance.py", line 465, in _execute_task
    result = _execute_callable(context=context, **execute_callable_kwargs)
             ^^^^^^^^^^^^^^^^^^^^^^^^^^^^^^^^^^^^^^^^^^^^^^^^^^^^^^^^^^^^^
  File "/home/airflow/.local/lib/python3.12/site-packages/airflow/models/taskinstance.py", line 432, in _execute_callable
    return execute_callable(context=context, **execute_callable_kwargs)
           ^^^^^^^^^^^^^^^^^^^^^^^^^^^^^^^^^^^^^^^^^^^^^^^^^^^^^^^^^^^^
  File "/home/airflow/.local/lib/python3.12/site-packages/airflow/models/baseoperator.py", line 401, in wrapper
    return func(self, *args, **kwargs)
           ^^^^^^^^^^^^^^^^^^^^^^^^^^^
  File "/home/airflow/.local/lib/python3.12/site-packages/airflow/decorators/base.py", line 265, in execute
    return_value = super().execute(context)
                   ^^^^^^^^^^^^^^^^^^^^^^^^
  File "/home/airflow/.local/lib/python3.12/site-packages/airflow/models/baseoperator.py", line 401, in wrapper
    return func(self, *args, **kwargs)
           ^^^^^^^^^^^^^^^^^^^^^^^^^^^
  File "/home/airflow/.local/lib/python3.12/site-packages/airflow/operators/python.py", line 235, in execute
    return_value = self.execute_callable()
                   ^^^^^^^^^^^^^^^^^^^^^^^
  File "/home/airflow/.local/lib/python3.12/site-packages/airflow/operators/python.py", line 252, in execute_callable
    return self.python_callable(*self.op_args, **self.op_kwargs)
           ^^^^^^^^^^^^^^^^^^^^^^^^^^^^^^^^^^^^^^^^^^^^^^^^^^^^^
  File "/opt/airflow/dags/data-ingestion.py", line 79, in ingest_from_mysql
    pipeline = Pipeline.create(
               ^^^^^^^^^^^^^^^^
  File "/home/airflow/.local/lib/python3.12/site-packages/datahub/ingestion/run/pipeline.py", line 393, in create
    return cls(
           ^^^^
  File "/home/airflow/.local/lib/python3.12/site-packages/datahub/ingestion/run/pipeline.py", line 269, in __init__
    with _add_init_error_context(
  File "/usr/local/lib/python3.12/contextlib.py", line 158, in __exit__
    self.gen.throw(value)
  File "/home/airflow/.local/lib/python3.12/site-packages/datahub/ingestion/run/pipeline.py", line 128, in _add_init_error_context
    raise PipelineInitError(f"Failed to {step}: {e}") from e
datahub.ingestion.run.pipeline.PipelineInitError: Failed to find a registered source for type mariadb: mariadb is disabled; try running: pip install 'acryl-datahub[mariadb]'
[2024-07-02T02:16:58.359+0000] {taskinstance.py:1206} INFO - Marking task as FAILED. dag_id=data-ingestion, task_id=ingest_from_mysql, run_id=scheduled__2024-06-30T15:05:00+00:00, execution_date=20240630T150500, start_date=20240702T021657, end_date=20240702T021658
[2024-07-02T02:16:58.383+0000] {standard_task_runner.py:110} ERROR - Failed to execute job 5 for task ingest_from_mysql (Failed to find a registered source for type mariadb: mariadb is disabled; try running: pip install 'acryl-datahub[mariadb]'; 284)
[2024-07-02T02:16:58.430+0000] {local_task_job_runner.py:240} INFO - Task exited with return code 1
[2024-07-02T02:16:58.448+0000] {taskinstance.py:3503} INFO - 0 downstream tasks scheduled from follow-on schedule check
[2024-07-02T02:16:58.450+0000] {local_task_job_runner.py:222} INFO - ::endgroup::
[2024-07-02T02:27:06.722+0000] {local_task_job_runner.py:120} INFO - ::group::Pre task execution logs
[2024-07-02T02:27:06.730+0000] {taskinstance.py:2076} INFO - Dependencies all met for dep_context=non-requeueable deps ti=<TaskInstance: data-ingestion.ingest_from_mysql scheduled__2024-06-30T15:05:00+00:00 [queued]>
[2024-07-02T02:27:06.735+0000] {taskinstance.py:2076} INFO - Dependencies all met for dep_context=requeueable deps ti=<TaskInstance: data-ingestion.ingest_from_mysql scheduled__2024-06-30T15:05:00+00:00 [queued]>
[2024-07-02T02:27:06.735+0000] {taskinstance.py:2306} INFO - Starting attempt 1 of 1
[2024-07-02T02:27:06.742+0000] {taskinstance.py:2330} INFO - Executing <Task(_PythonDecoratedOperator): ingest_from_mysql> on 2024-06-30 15:05:00+00:00
[2024-07-02T02:27:06.750+0000] {logging_mixin.py:188} WARNING - /home/***/.local/lib/python3.12/site-packages/***/task/task_runner/standard_task_runner.py:61 DeprecationWarning: This process (pid=376) is multi-threaded, use of fork() may lead to deadlocks in the child.
[2024-07-02T02:27:06.751+0000] {standard_task_runner.py:63} INFO - Started process 377 to run task
[2024-07-02T02:27:06.750+0000] {standard_task_runner.py:90} INFO - Running: ['***', 'tasks', 'run', 'data-ingestion', 'ingest_from_mysql', 'scheduled__2024-06-30T15:05:00+00:00', '--job-id', '7', '--raw', '--subdir', 'DAGS_FOLDER/data-ingestion.py', '--cfg-path', '/tmp/tmpwti5t2kt']
[2024-07-02T02:27:06.752+0000] {standard_task_runner.py:91} INFO - Job 7: Subtask ingest_from_mysql
[2024-07-02T02:27:06.760+0000] {logging_mixin.py:188} WARNING - /home/***/.local/lib/python3.12/site-packages/***/settings.py:195 DeprecationWarning: The sql_alchemy_conn option in [core] has been moved to the sql_alchemy_conn option in [database] - the old setting has been used, but please update your config.
[2024-07-02T02:27:06.789+0000] {task_command.py:426} INFO - Running <TaskInstance: data-ingestion.ingest_from_mysql scheduled__2024-06-30T15:05:00+00:00 [running]> on host ***-scheduler
[2024-07-02T02:27:06.892+0000] {taskinstance.py:2648} INFO - Exporting env vars: AIRFLOW_CTX_DAG_OWNER='***' AIRFLOW_CTX_DAG_ID='data-ingestion' AIRFLOW_CTX_TASK_ID='ingest_from_mysql' AIRFLOW_CTX_EXECUTION_DATE='2024-06-30T15:05:00+00:00' AIRFLOW_CTX_TRY_NUMBER='1' AIRFLOW_CTX_DAG_RUN_ID='scheduled__2024-06-30T15:05:00+00:00'
[2024-07-02T02:27:07.310+0000] {taskinstance.py:430} INFO - ::endgroup::
[2024-07-02T02:27:07.402+0000] {pipeline.py:257} INFO - Sink configured successfully. DataHubRestEmitter: configured to talk to http://datahub-gms:8080
[2024-07-02T02:27:07.428+0000] {taskinstance.py:441} INFO - ::group::Post task execution logs
[2024-07-02T02:27:07.512+0000] {taskinstance.py:2905} ERROR - Task failed with exception
Traceback (most recent call last):
  File "/home/airflow/.local/lib/python3.12/site-packages/datahub/ingestion/api/registry.py", line 126, in _ensure_not_lazy
    plugin_class = import_path(path)
                   ^^^^^^^^^^^^^^^^^
  File "/home/airflow/.local/lib/python3.12/site-packages/datahub/ingestion/api/registry.py", line 56, in import_path
    item = importlib.import_module(module_name)
           ^^^^^^^^^^^^^^^^^^^^^^^^^^^^^^^^^^^^
  File "/usr/local/lib/python3.12/importlib/__init__.py", line 90, in import_module
    return _bootstrap._gcd_import(name[level:], package, level)
           ^^^^^^^^^^^^^^^^^^^^^^^^^^^^^^^^^^^^^^^^^^^^^^^^^^^^
  File "<frozen importlib._bootstrap>", line 1387, in _gcd_import
  File "<frozen importlib._bootstrap>", line 1360, in _find_and_load
  File "<frozen importlib._bootstrap>", line 1331, in _find_and_load_unlocked
  File "<frozen importlib._bootstrap>", line 935, in _load_unlocked
  File "<frozen importlib._bootstrap_external>", line 995, in exec_module
  File "<frozen importlib._bootstrap>", line 488, in _call_with_frames_removed
  File "/home/airflow/.local/lib/python3.12/site-packages/datahub/ingestion/source/sql/mariadb.py", line 9, in <module>
    from datahub.ingestion.source.sql.mysql import MySQLConfig, MySQLSource
  File "/home/airflow/.local/lib/python3.12/site-packages/datahub/ingestion/source/sql/mysql.py", line 3, in <module>
    import pymysql  # noqa: F401
    ^^^^^^^^^^^^^^
ModuleNotFoundError: No module named 'pymysql'

The above exception was the direct cause of the following exception:

Traceback (most recent call last):
  File "/home/airflow/.local/lib/python3.12/site-packages/datahub/ingestion/run/pipeline.py", line 124, in _add_init_error_context
    yield
  File "/home/airflow/.local/lib/python3.12/site-packages/datahub/ingestion/run/pipeline.py", line 272, in __init__
    source_class = source_registry.get(self.source_type)
                   ^^^^^^^^^^^^^^^^^^^^^^^^^^^^^^^^^^^^^
  File "/home/airflow/.local/lib/python3.12/site-packages/datahub/ingestion/api/registry.py", line 176, in get
    raise ConfigurationError(
datahub.configuration.common.ConfigurationError: mariadb is disabled; try running: pip install 'acryl-datahub[mariadb]'

The above exception was the direct cause of the following exception:

Traceback (most recent call last):
  File "/home/airflow/.local/lib/python3.12/site-packages/airflow/models/taskinstance.py", line 465, in _execute_task
    result = _execute_callable(context=context, **execute_callable_kwargs)
             ^^^^^^^^^^^^^^^^^^^^^^^^^^^^^^^^^^^^^^^^^^^^^^^^^^^^^^^^^^^^^
  File "/home/airflow/.local/lib/python3.12/site-packages/airflow/models/taskinstance.py", line 432, in _execute_callable
    return execute_callable(context=context, **execute_callable_kwargs)
           ^^^^^^^^^^^^^^^^^^^^^^^^^^^^^^^^^^^^^^^^^^^^^^^^^^^^^^^^^^^^
  File "/home/airflow/.local/lib/python3.12/site-packages/airflow/models/baseoperator.py", line 401, in wrapper
    return func(self, *args, **kwargs)
           ^^^^^^^^^^^^^^^^^^^^^^^^^^^
  File "/home/airflow/.local/lib/python3.12/site-packages/airflow/decorators/base.py", line 265, in execute
    return_value = super().execute(context)
                   ^^^^^^^^^^^^^^^^^^^^^^^^
  File "/home/airflow/.local/lib/python3.12/site-packages/airflow/models/baseoperator.py", line 401, in wrapper
    return func(self, *args, **kwargs)
           ^^^^^^^^^^^^^^^^^^^^^^^^^^^
  File "/home/airflow/.local/lib/python3.12/site-packages/airflow/operators/python.py", line 235, in execute
    return_value = self.execute_callable()
                   ^^^^^^^^^^^^^^^^^^^^^^^
  File "/home/airflow/.local/lib/python3.12/site-packages/airflow/operators/python.py", line 252, in execute_callable
    return self.python_callable(*self.op_args, **self.op_kwargs)
           ^^^^^^^^^^^^^^^^^^^^^^^^^^^^^^^^^^^^^^^^^^^^^^^^^^^^^
  File "/opt/airflow/dags/data-ingestion.py", line 79, in ingest_from_mysql
    pipeline = Pipeline.create(
               ^^^^^^^^^^^^^^^^
  File "/home/airflow/.local/lib/python3.12/site-packages/datahub/ingestion/run/pipeline.py", line 393, in create
    return cls(
           ^^^^
  File "/home/airflow/.local/lib/python3.12/site-packages/datahub/ingestion/run/pipeline.py", line 269, in __init__
    with _add_init_error_context(
  File "/usr/local/lib/python3.12/contextlib.py", line 158, in __exit__
    self.gen.throw(value)
  File "/home/airflow/.local/lib/python3.12/site-packages/datahub/ingestion/run/pipeline.py", line 128, in _add_init_error_context
    raise PipelineInitError(f"Failed to {step}: {e}") from e
datahub.ingestion.run.pipeline.PipelineInitError: Failed to find a registered source for type mariadb: mariadb is disabled; try running: pip install 'acryl-datahub[mariadb]'
[2024-07-02T02:27:07.527+0000] {taskinstance.py:1206} INFO - Marking task as FAILED. dag_id=data-ingestion, task_id=ingest_from_mysql, run_id=scheduled__2024-06-30T15:05:00+00:00, execution_date=20240630T150500, start_date=20240702T022706, end_date=20240702T022707
[2024-07-02T02:27:07.536+0000] {standard_task_runner.py:110} ERROR - Failed to execute job 7 for task ingest_from_mysql (Failed to find a registered source for type mariadb: mariadb is disabled; try running: pip install 'acryl-datahub[mariadb]'; 377)
[2024-07-02T02:27:07.550+0000] {local_task_job_runner.py:240} INFO - Task exited with return code 1
[2024-07-02T02:27:07.558+0000] {taskinstance.py:3503} INFO - 0 downstream tasks scheduled from follow-on schedule check
[2024-07-02T02:27:07.559+0000] {local_task_job_runner.py:222} INFO - ::endgroup::
